Traceback (most recent call last):
  File "/usr/irissys/mgr/python/intersystems_iris/dbapi/_DBAPI.py", line 37, in connect
    return native_connect(*args, hostname=hostname, port=port, namespace=namespace, username=username, password=password, **kw)
  File "/usr/irissys/mgr/python/intersystems_iris/_IRISNative.py", line 183, in connect
    connection._connect(hostname, port, namespace, username, password, timeout, sharedmemory, logfile, sslcontext, autoCommit, isolationLevel, featureOptions, application_name)
  File "/usr/irissys/mgr/python/intersystems_iris/_IRISConnection.py", line 304, in _connect
    raise e
  File "/usr/irissys/mgr/python/intersystems_iris/_IRISConnection.py", line 212, in _connect
    self._in_message._read_message_sql(sequence_number)
  File "/usr/irissys/mgr/python/intersystems_iris/_InStream.py", line 46, in _read_message_sql
    is_for_gateway = self.__read_message_internal(expected_message_id, expected_statement_id, type)
  File "/usr/irissys/mgr/python/intersystems_iris/_InStream.py", line 59, in __read_message_internal
    self.__read_buffer(header.buffer, 0, _MessageHeader.HEADER_SIZE)
  File "/usr/irissys/mgr/python/intersystems_iris/_InStream.py", line 146, in __read_buffer
    raise Exception("Server unexpectedly closing communication device")
Exception: Server unexpectedly closing communication device

During handling of the above exception, another exception occurred:

Traceback (most recent call last):
  File "/usr/irissys/mgr/python/sqlalchemy/engine/base.py", line 3361, in _wrap_pool_connect
    return fn()
  File "/usr/irissys/mgr/python/sqlalchemy/pool/base.py", line 327, in connect
    return _ConnectionFairy._checkout(self)
  File "/usr/irissys/mgr/python/sqlalchemy/pool/base.py", line 894, in _checkout
    fairy = _ConnectionRecord.checkout(pool)
  File "/usr/irissys/mgr/python/sqlalchemy/pool/base.py", line 493, in checkout
    rec = pool._do_get()
  File "/usr/irissys/mgr/python/sqlalchemy/pool/impl.py", line 145, in _do_get
    with util.safe_reraise():
  File "/usr/irissys/mgr/python/sqlalchemy/util/langhelpers.py", line 70, in __exit__
    compat.raise_(
  File "/usr/irissys/mgr/python/sqlalchemy/util/compat.py", line 211, in raise_
    raise exception
  File "/usr/irissys/mgr/python/sqlalchemy/pool/impl.py", line 143, in _do_get
    return self._create_connection()
  File "/usr/irissys/mgr/python/sqlalchemy/pool/base.py", line 273, in _create_connection
    return _ConnectionRecord(self)
  File "/usr/irissys/mgr/python/sqlalchemy/pool/base.py", line 388, in __init__
    self.__connect()
  File "/usr/irissys/mgr/python/sqlalchemy/pool/base.py", line 690, in __connect
    with util.safe_reraise():
  File "/usr/irissys/mgr/python/sqlalchemy/util/langhelpers.py", line 70, in __exit__
    compat.raise_(
  File "/usr/irissys/mgr/python/sqlalchemy/util/compat.py", line 211, in raise_
    raise exception
  File "/usr/irissys/mgr/python/sqlalchemy/pool/base.py", line 686, in __connect
    self.dbapi_connection = connection = pool._invoke_creator(self)
  File "/usr/irissys/mgr/python/sqlalchemy/engine/create.py", line 574, in connect
    return dialect.connect(*cargs, **cparams)
  File "/usr/irissys/mgr/python/sqlalchemy/engine/default.py", line 598, in connect
    return self.dbapi.connect(*cargs, **cparams)
  File "/usr/irissys/mgr/python/intersystems_iris/dbapi/_DBAPI.py", line 41, in connect
    raise DatabaseError(e)
intersystems_iris.dbapi._DBAPI.DatabaseError: Server unexpectedly closing communication device

The above exception was the direct cause of the following exception:

Traceback (most recent call last):
  File "/home/irisowner/irisdev/python/audit.py", line 36, in <module>
    df2.to_sql('USERCHANGE', engine_cloud, schema="otw_audit" ,if_exists='replace', index=True,
  File "/usr/irissys/mgr/python/pandas/core/generic.py", line 2987, in to_sql
    return sql.to_sql(
  File "/usr/irissys/mgr/python/pandas/io/sql.py", line 695, in to_sql
    return pandas_sql.to_sql(
  File "/usr/irissys/mgr/python/pandas/io/sql.py", line 1728, in to_sql
    table = self.prep_table(
  File "/usr/irissys/mgr/python/pandas/io/sql.py", line 1631, in prep_table
    table.create()
  File "/usr/irissys/mgr/python/pandas/io/sql.py", line 827, in create
    if self.exists():
  File "/usr/irissys/mgr/python/pandas/io/sql.py", line 814, in exists
    return self.pd_sql.has_table(self.name, self.schema)
  File "/usr/irissys/mgr/python/pandas/io/sql.py", line 1760, in has_table
    insp = sqlalchemy_inspect(self.connectable)
  File "/usr/irissys/mgr/python/sqlalchemy/inspection.py", line 64, in inspect
    ret = reg(subject)
  File "/usr/irissys/mgr/python/sqlalchemy/engine/reflection.py", line 182, in _engine_insp
    return Inspector._construct(Inspector._init_engine, bind)
  File "/usr/irissys/mgr/python/sqlalchemy/engine/reflection.py", line 117, in _construct
    init(self, bind)
  File "/usr/irissys/mgr/python/sqlalchemy/engine/reflection.py", line 128, in _init_engine
    engine.connect().close()
  File "/usr/irissys/mgr/python/sqlalchemy/engine/base.py", line 3315, in connect
    return self._connection_cls(self, close_with_result=close_with_result)
  File "/usr/irissys/mgr/python/sqlalchemy/engine/base.py", line 96, in __init__
    else engine.raw_connection()
  File "/usr/irissys/mgr/python/sqlalchemy/engine/base.py", line 3394, in raw_connection
    return self._wrap_pool_connect(self.pool.connect, _connection)
  File "/usr/irissys/mgr/python/sqlalchemy/engine/base.py", line 3364, in _wrap_pool_connect
    Connection._handle_dbapi_exception_noconnection(
  File "/usr/irissys/mgr/python/sqlalchemy/engine/base.py", line 2198, in _handle_dbapi_exception_noconnection
    util.raise_(
  File "/usr/irissys/mgr/python/sqlalchemy/util/compat.py", line 211, in raise_
    raise exception
  File "/usr/irissys/mgr/python/sqlalchemy/engine/base.py", line 3361, in _wrap_pool_connect
    return fn()
  File "/usr/irissys/mgr/python/sqlalchemy/pool/base.py", line 327, in connect
    return _ConnectionFairy._checkout(self)
  File "/usr/irissys/mgr/python/sqlalchemy/pool/base.py", line 894, in _checkout
    fairy = _ConnectionRecord.checkout(pool)
  File "/usr/irissys/mgr/python/sqlalchemy/pool/base.py", line 493, in checkout
    rec = pool._do_get()
  File "/usr/irissys/mgr/python/sqlalchemy/pool/impl.py", line 145, in _do_get
    with util.safe_reraise():
  File "/usr/irissys/mgr/python/sqlalchemy/util/langhelpers.py", line 70, in __exit__
    compat.raise_(
  File "/usr/irissys/mgr/python/sqlalchemy/util/compat.py", line 211, in raise_
    raise exception
  File "/usr/irissys/mgr/python/sqlalchemy/pool/impl.py", line 143, in _do_get
    return self._create_connection()
  File "/usr/irissys/mgr/python/sqlalchemy/pool/base.py", line 273, in _create_connection
    return _ConnectionRecord(self)
  File "/usr/irissys/mgr/python/sqlalchemy/pool/base.py", line 388, in __init__
    self.__connect()
  File "/usr/irissys/mgr/python/sqlalchemy/pool/base.py", line 690, in __connect
    with util.safe_reraise():
  File "/usr/irissys/mgr/python/sqlalchemy/util/langhelpers.py", line 70, in __exit__
    compat.raise_(
  File "/usr/irissys/mgr/python/sqlalchemy/util/compat.py", line 211, in raise_
    raise exception
  File "/usr/irissys/mgr/python/sqlalchemy/pool/base.py", line 686, in __connect
    self.dbapi_connection = connection = pool._invoke_creator(self)
  File "/usr/irissys/mgr/python/sqlalchemy/engine/create.py", line 574, in connect
    return dialect.connect(*cargs, **cparams)
  File "/usr/irissys/mgr/python/sqlalchemy/engine/default.py", line 598, in connect
    return self.dbapi.connect(*cargs, **cparams)
  File "/usr/irissys/mgr/python/intersystems_iris/dbapi/_DBAPI.py", line 41, in connect
    raise DatabaseError(e)
sqlalchemy.exc.DatabaseError: (intersystems_iris.dbapi._DBAPI.DatabaseError) Server unexpectedly closing communication device
(Background on this error at: https://sqlalche.me/e/14/4xp6)
